<?xml version="1.0" ?>
<robot name="edmo_assembly" xmlns:xacro="http://www.ros.org/wiki/xacro">

<xacro:include filename="$(find edmo_assembly_description)/urdf/materials.xacro" />
<xacro:include filename="$(find edmo_assembly_description)/urdf/edmo_assembly.trans" />
<xacro:include filename="$(find edmo_assembly_description)/urdf/edmo_assembly.gazebo" />
<link name="base_link">
  <inertial>
    <origin xyz="0.0023065695021034353 0.033691720135630446 0.012783324748844338" rpy="0 0 0"/>
    <mass value="0.03847845253485034"/>
    <inertia ixx="3.3e-05" iyy="2.2e-05" izz="4.9e-05" ixy="-2e-06" iyz="3e-06" ixz="-0.0"/>
  </inertial>
  <visual>
    <origin xyz="0 0 0" rpy="0 0 0"/>
    <geometry>
      <mesh filename="package://edmo_assembly_description/meshes/base_link.stl" scale="0.001 0.001 0.001"/>
    </geometry>
    <material name="silver"/>
  </visual>
  <collision>
    <origin xyz="0 0 0" rpy="0 0 0"/>
    <geometry>
      <mesh filename="package://edmo_assembly_description/meshes/base_link.stl" scale="0.001 0.001 0.001"/>
    </geometry>
  </collision>
</link>

<link name="cover_1_1">
  <inertial>
    <origin xyz="-0.01692979747824099 -0.02470422851834657 0.008505653303175383" rpy="0 0 0"/>
    <mass value="0.014555566232575165"/>
    <inertia ixx="8e-06" iyy="3e-06" izz="1e-05" ixy="0.0" iyz="-0.0" ixz="-0.0"/>
  </inertial>
  <visual>
    <origin xyz="-0.018186 -0.082013 -0.016112" rpy="0 0 0"/>
    <geometry>
      <mesh filename="package://edmo_assembly_description/meshes/cover_1_1.stl" scale="0.001 0.001 0.001"/>
    </geometry>
    <material name="silver"/>
  </visual>
  <collision>
    <origin xyz="-0.018186 -0.082013 -0.016112" rpy="0 0 0"/>
    <geometry>
      <mesh filename="package://edmo_assembly_description/meshes/cover_1_1.stl" scale="0.001 0.001 0.001"/>
    </geometry>
  </collision>
</link>

<link name="arm_1_1">
  <inertial>
    <origin xyz="0.02261233759672383 0.023394700602238833 -0.05118896256969527" rpy="0 0 0"/>
    <mass value="0.03728860045356832"/>
    <inertia ixx="3.7e-05" iyy="4.1e-05" izz="7.3e-05" ixy="-0.0" iyz="0.0" ixz="-0.0"/>
  </inertial>
  <visual>
    <origin xyz="0.0225 -0.073176 -0.067176" rpy="0 0 0"/>
    <geometry>
      <mesh filename="package://edmo_assembly_description/meshes/arm_1_1.stl" scale="0.001 0.001 0.001"/>
    </geometry>
    <material name="silver"/>
  </visual>
  <collision>
    <origin xyz="0.0225 -0.073176 -0.067176" rpy="0 0 0"/>
    <geometry>
      <mesh filename="package://edmo_assembly_description/meshes/arm_1_1.stl" scale="0.001 0.001 0.001"/>
    </geometry>
  </collision>
</link>

<joint name="Rigid4" type="fixed">
  <origin xyz="0.018186 0.082013 0.016112" rpy="0 0 0"/>
  <parent link="base_link"/>
  <child link="cover_1_1"/>
</joint>

<joint name="Rev5" type="continuous">
  <origin xyz="-0.0225 0.073176 0.067176" rpy="0 0 0"/>
  <parent link="base_link"/>
  <child link="arm_1_1"/>
  <axis xyz="-1.0 -0.0 0.0"/>
</joint>

</robot>
